Workbook

Sheet Index
A1: Jopetnah International Limited — Loan Management System
A2: Empowering Businesses with Practical Solutions. A working loan portfolio tracking tool — not a substitute for a licensed core banking system.
A4: How the Workbook Fits Together
A5: 1. Set up PRODUCTS once. 2. Register borrowers in BORROWERS. 3. Log every request in APPLICATIONS. 4. On approval and disbursement, create the loan in PORTFOLIO (the master ledger everything else rolls up from). 5. Record guarantors and collateral against the Loan ID. 6. Log every payment in REPAYMENTS as it arrives. 7. Monitor ARREARS-PAR and the DASHBOARD. 8. Use AMORT to print or review one loan's full schedule. 9. If a loan becomes unrecoverable, record it in WRITEOFFS and update its Status in PORTFOLIO.
A7: Key Assumptions — Read Before Relying on the Numbers
A8: • Amortisation assumes MONTHLY repayments. Weekly and Bi-Weekly loans can still be recorded (for reference), but the automatic schedule, arrears and PAR formulas will not be accurate for them — calculate those manually.
A9: • "Outstanding Balance" on PORTFOLIO is Total Repayable minus Total Paid — the full remaining principal-plus-interest obligation under the original schedule. It is not a precise principal-only early-settlement figure; use AMORT for that.
A10: • Arrears are estimated by comparing the number of installments that should have fallen due by today against what has actually been paid, then working out which installment's due date that shortfall traces back to. This is a reasonable portfolio-level approximation, not a payment-by-payment reconciliation.
A11: • The AMORT schedule generator is capped at 60 installments (5 years monthly).
A12: • Interest rate and method on each PORTFOLIO loan are independently editable from the Product's standard card, to allow for negotiated terms — the "Suggested" columns are reference only and do not constrain the actual fields.
A14: Regulatory Note
A15: Money-lending and microfinance activity in Uganda is regulated — among others, by the Tier 4 Microfinance Institutions and Money Lenders Act, 2016 (Uganda Microfinance Regulatory Authority) and, for deposit-taking institutions, the Financial Institutions Act. This workbook is an operational tracking tool only; it does not establish, confirm or substitute for any licence Jopetnah may need to conduct lending activity. Add the applicable licence to the LIC sheet of the Asset & Compliance Registers workbook, and confirm licensing status with your legal or compliance advisor before relying on this system for live lending.
A17: Version Control
A18: Version | B18: Date | C18: Summary of Changes | D18: Approved By
A19: 1.0 | B19: 01 Oct 2026 | C19: First issue of the Loan Management System. | D19: Managing Director
A21: Sheet Index
A22: Code | B22: Sheet | C22: Purpose
A23: PRODUCTS | B23: Loan Products & Rate Card | C23: Set up every loan product once here — everything else in the workbook refers back to it
A24: BORROWERS | B24: Borrower Register (KYC) | C24: Human client / customer master file — one row per borrower
A25: GUARANTORS | B25: Guarantor Register | C25: Everyone standing surety for a loan, linked to the loan they guarantee
A26: COLLATERAL | B26: Collateral Register | C26: Security pledged against loans, linked back to PORTFOLIO
A27: APPLICATIONS | B27: Loan Application Register | C27: Every request received, from intake through to the approval decision
A28: PORTFOLIO | B28: Loan Portfolio Register (Master Ledger) | C28: The central record of every loan — one row per disbursed loan; everything else in the workbook rolls up from here
A29: REPAYMENTS | B29: Repayment / Collections Register | C29: Every payment received against a loan — PORTFOLIO totals roll up from here
A30: ARREARS-PAR | B30: Arrears & Portfolio-at-Risk (PAR) Report | C30: Risk Management — aging analysis of the live loan book
A31: OFFICER-PERF | B31: Loan Officer Performance | C31: Type each officer's name once below — every metric calculates from PORTFOLIO and REPAYMENTS
A32: WRITEOFFS | B32: Write-off Register | C32: Loans formally removed from the active portfolio as bad debt
A33: AMORT | B33: Loan Amortisation Schedule (Single Loan) | C33: Printable repayment schedule for one loan at a time
A34: DASHBOARD | B34: Loan Portfolio Dashboard | C34: Live summary — recalculates from PRODUCTS, BORROWERS, PORTFOLIO, REPAYMENTS, ARREARS-PAR and WRITEOFFS

Sheet DASHBOARD
A1: DASHBOARD | Loan Portfolio Dashboard
A2: Jopetnah International Limited | Version 1.0 | As at 01 Oct 2026 | Live summary — recalculates from PRODUCTS, BORROWERS, PORTFOLIO, REPAYMENTS, ARREARS-PAR and WRITEOFFS
A4: Total Borrowers | C4: Total Loans (all-time) | E4: Active Loans | G4: Total Disbursed (UGX, all-time) | I4: Total Outstanding (UGX, live)
A5: =COUNTIFS(BORROWERS!$B$6:$B$55,"<>",BORROWERS!$A$6:$A$55,"<>EXAMPLE") -> 0 | C5: =COUNTIFS(PORTFOLIO!$A$6:$A$55,"<>",PORTFOLIO!$B$6:$B$55,"<>EXAMPLE") -> 0 | E5: =COUNTIFS(PORTFOLIO!$A$6:$A$55,"<>",PORTFOLIO!$B$6:$B$55,"<>EXAMPLE",PORTFOLIO!$Z$6:$Z$55,"Active") -> 0 | G5: =SUMIFS(PORTFOLIO!$K$6:$K$55,PORTFOLIO!$A$6:$A$55,"<>",PORTFOLIO!$B$6:$B$55,"<>EXAMPLE") -> 0 | I5: =SUMIFS(PORTFOLIO!$U$6:$U$55,PORTFOLIO!$Z$6:$Z$55,"<>Written Off",PORTFOLIO!$A$6:$A$55,"<>",PORTFOLIO!$B$6:$B$55,"<>EXAMPLE") -> 0
A7: Total Collected (UGX, all-time) | C7: Loans in Arrears | E7: PAR > 30 Days | G7: PAR > 90 Days | I7: Total Written Off (UGX) | K7: Average Loan Size (UGX)
A8: =SUMIFS(REPAYMENTS!$F$5:$F$104,REPAYMENTS!$C$5:$C$104,"<>",REPAYMENTS!$A$5:$A$104,"<>EXAMPLE") -> 0 | C8: =COUNTIFS(PORTFOLIO!$A$6:$A$55,"<>",PORTFOLIO!$W$6:$W$55,">0") -> 1 | E8: ='ARREARS-PAR'!B16 | G8: ='ARREARS-PAR'!B17 | I8: =SUMIF(WRITEOFFS!$B$6:$B$25,"<>",WRITEOFFS!$E$6:$E$25) -> 0 | K8: =IFERROR(SUMIFS(PORTFOLIO!$K$6:$K$55,PORTFOLIO!$A$6:$A$55,"<>",PORTFOLIO!$B$6:$B$55,"<>EXAMPLE")/COUNTIFS(PORTFOLIO!$A$6:$A$55,"<>",PORTFOLIO!$B$6:$B$55,"<>EXAMPLE"),"")
A10: Figures above are correct once PORTFOLIO, REPAYMENTS and WRITEOFFS contain real data — the EXAMPLE rows are excluded automatically.
A12: Live Outstanding by Loan Product | D12: Portfolio-at-Risk Ageing | G12: Live Outstanding by Branch
A13: Product | B13: Outstanding (UGX) | D13: Bucket | E13: Outstanding (UGX) | G13: Branch | H13: Outstanding (UGX)
A14: =PRODUCTS!$B$6 -> Business Growth Loan | B14: =IF(PRODUCTS!$B$6="","",SUMIFS(PORTFOLIO!$U$6:$U$55,PORTFOLIO!$F$6:$F$55,PRODUCTS!$B$6,PORTFOLIO!$Z$6:$Z$55,"<>Written Off")) -> 5202840.8 | D14: ='ARREARS-PAR'!A6 -> Current | E14: ='ARREARS-PAR'!C6 -> 0 | G14: Kampala (Head Office) | H14: =SUMIFS(PORTFOLIO!$U$6:$U$55,PORTFOLIO!$D$6:$D$55,"Kampala (Head Office)",PORTFOLIO!$Z$6:$Z$55,"<>Written Off") -> 5202840.8
A15: =PRODUCTS!$B$7 -> Agribusiness Loan | B15: =IF(PRODUCTS!$B$7="","",SUMIFS(PORTFOLIO!$U$6:$U$55,PORTFOLIO!$F$6:$F$55,PRODUCTS!$B$7,PORTFOLIO!$Z$6:$Z$55,"<>Written Off")) -> 0 | D15: ='ARREARS-PAR'!A7 -> 1-30 Days | E15: ='ARREARS-PAR'!C7 -> 0 | G15: Jinja | H15: =SUMIFS(PORTFOLIO!$U$6:$U$55,PORTFOLIO!$D$6:$D$55,"Jinja",PORTFOLIO!$Z$6:$Z$55,"<>Written Off") -> 0
A16: =PRODUCTS!$B$8 -> Emergency / Salary Advance | B16: =IF(PRODUCTS!$B$8="","",SUMIFS(PORTFOLIO!$U$6:$U$55,PORTFOLIO!$F$6:$F$55,PRODUCTS!$B$8,PORTFOLIO!$Z$6:$Z$55,"<>Written Off")) -> 0 | D16: ='ARREARS-PAR'!A8 -> 31-60 Days | E16: ='ARREARS-PAR'!C8 -> 0 | G16: Mbarara | H16: =SUMIFS(PORTFOLIO!$U$6:$U$55,PORTFOLIO!$D$6:$D$55,"Mbarara",PORTFOLIO!$Z$6:$Z$55,"<>Written Off") -> 0
A17: =PRODUCTS!$B$9 -> 0 | B17: =IF(PRODUCTS!$B$9="","",SUMIFS(PORTFOLIO!$U$6:$U$55,PORTFOLIO!$F$6:$F$55,PRODUCTS!$B$9,PORTFOLIO!$Z$6:$Z$55,"<>Written Off")) | D17: ='ARREARS-PAR'!A9 -> 61-90 Days | E17: ='ARREARS-PAR'!C9 -> 0 | G17: Gulu | H17: =SUMIFS(PORTFOLIO!$U$6:$U$55,PORTFOLIO!$D$6:$D$55,"Gulu",PORTFOLIO!$Z$6:$Z$55,"<>Written Off") -> 0
A18: =PRODUCTS!$B$10 -> 0 | B18: =IF(PRODUCTS!$B$10="","",SUMIFS(PORTFOLIO!$U$6:$U$55,PORTFOLIO!$F$6:$F$55,PRODUCTS!$B$10,PORTFOLIO!$Z$6:$Z$55,"<>Written Off")) | D18: ='ARREARS-PAR'!A10 -> 90+ Days (PAR90) | E18: ='ARREARS-PAR'!C10 -> 0 | G18: Mbale | H18: =SUMIFS(PORTFOLIO!$U$6:$U$55,PORTFOLIO!$D$6:$D$55,"Mbale",PORTFOLIO!$Z$6:$Z$55,"<>Written Off") -> 0
A19: Shows only the first 5 rows of PRODUCTS; add more products there and extend this range if you use more than 5 active products. | D19: ='ARREARS-PAR'!A11 -> Written Off | E19: ='ARREARS-PAR'!C11 -> 0 | G19: Arua | H19: =SUMIFS(PORTFOLIO!$U$6:$U$55,PORTFOLIO!$D$6:$D$55,"Arua",PORTFOLIO!$Z$6:$Z$55,"<>Written Off") -> 0
G20: Fort Portal | H20: =SUMIFS(PORTFOLIO!$U$6:$U$55,PORTFOLIO!$D$6:$D$55,"Fort Portal",PORTFOLIO!$Z$6:$Z$55,"<>Written Off") -> 0
G21: Hoima | H21: =SUMIFS(PORTFOLIO!$U$6:$U$55,PORTFOLIO!$D$6:$D$55,"Hoima",PORTFOLIO!$Z$6:$Z$55,"<>Written Off") -> 0
G22: Adjumani | H22: =SUMIFS(PORTFOLIO!$U$6:$U$55,PORTFOLIO!$D$6:$D$55,"Adjumani",PORTFOLIO!$Z$6:$Z$55,"<>Written Off") -> 0
G23: Other | H23: =SUMIFS(PORTFOLIO!$U$6:$U$55,PORTFOLIO!$D$6:$D$55,"Other",PORTFOLIO!$Z$6:$Z$55,"<>Written Off") -> 0

Sheet Lists
A1: Branch / Location | B1: Interest Method | C1: Repayment Frequency | D1: Loan Status | E1: Application Status | F1: Payment Method | G1: Collateral Type | H1: Collateral Status | I1: Credit Rating | J1: Product Status | K1: KYC on File (Y/N) | M1: Editable option lists behind every dropdown in this workbook. Loan Products, Loan IDs and Borrower Names are NOT here — those dropdowns pull live from the Products / Portfolio / Borrowers sheets instead.
A2: Kampala (Head Office) | B2: Reducing Balance | C2: Monthly | D2: Active | E2: Pending | F2: Cash | G2: Land Title | H2: Held | I2: A - Excellent | J2: Active | K2: Y
A3: Jinja | B3: Flat Rate | C3: Weekly | D3: Fully Paid | E3: Under Review | F3: Mobile Money | G3: Vehicle Logbook | H3: Released | I3: B - Good | J3: Inactive | K3: N
A4: Mbarara | C4: Bi-Weekly (Fortnightly) | D4: Restructured | E4: Approved | F4: Bank Transfer | G4: Household Goods / Chattels | H4: Sold | I4: C - Fair
A5: Gulu | C5: Lump Sum (Bullet) | D5: Defaulted | E5: Rejected | F5: Cheque | G5: Business Stock | H5: Repossessed | I5: D - Poor / High Risk
A6: Mbale | D6: Written Off | E6: Disbursed | G6: Salary / Payslip Assignment
A7: Arua | E7: Cancelled | G7: Group Guarantee
A8: Fort Portal | G8: None
A9: Hoima | G9: Other
A10: Adjumani
A11: Other

Sheet PRODUCTS
A1: PRODUCTS | Loan Products & Rate Card
A2: Jopetnah International Limited | Version 1.0 | As at 01 Oct 2026 | Set up every loan product once here — everything else in the workbook refers back to it
A3: Define each loan product's terms here before creating loans against it in PORTFOLIO. "Interest Method" drives the amortisation formulas used across the workbook: Reducing Balance (interest recalculated on the falling balance each period) or Flat Rate (interest fixed on the original principal for the full term). Replace the EXAMPLE rows with your real products.
A5: Product Code | B5: Product Name | C5: Interest Method | D5: Interest Rate (% p.a.) | E5: Min Amount (UGX) | F5: Max Amount (UGX) | G5: Min Term (Months) | H5: Max Term (Months) | I5: Processing Fee (%) | J5: Insurance / Other Fee (%) | K5: Late Payment Penalty (% per month overdue) | L5: Grace Period (Days) | M5: Target Segment | N5: Status | O5: Notes
A6: EXAMPLE | B6: Business Growth Loan | C6: Reducing Balance | D6: 24 | E6: 500000 | F6: 20000000 | G6: 3 | H6: 24 | I6: 2 | J6: 1 | K6: 5 | L6: 7 | M6: SMEs & Traders | N6: Active | O6: Example — replace or delete.
A7: EXAMPLE | B7: Agribusiness Loan | C7: Reducing Balance | D7: 20 | E7: 300000 | F7: 15000000 | G7: 3 | H7: 18 | I7: 2 | J7: 1 | K7: 5 | L7: 14 | M7: Agricultural Sector (Sector 15) | N7: Active | O7: Example — replace or delete.
A8: EXAMPLE | B8: Emergency / Salary Advance | C8: Flat Rate | D8: 10 | E8: 100000 | F8: 3000000 | G8: 1 | H8: 6 | I8: 1 | J8: 0 | K8: 10 | L8: 0 | M8: Salaried Individuals | N8: Active | O8: Example — flat-rate example. Replace or delete.

Sheet BORROWERS
A1: BORROWERS | Borrower Register (KYC)
A2: Jopetnah International Limited | Version 1.0 | As at 01 Oct 2026 | Human client / customer master file — one row per borrower
A3: Every borrower must appear here before a loan is created for them in PORTFOLIO. Age calculates automatically from Date of Birth.
A5: Borrower ID | B5: Full Name | C5: National ID / Passport No. | D5: Date of Birth | E5: Age | F5: Gender | G5: Phone Number | H5: Email | I5: Physical Address | J5: Branch / Location | K5: Occupation / Business Type | L5: Monthly Income (UGX) | M5: Credit Rating | N5: Date Registered | O5: KYC Documents on File (Y/N) | P5: Next of Kin Name | Q5: Next of Kin Phone | R5: Relationship | S5: Notes
A6: EXAMPLE | B6: Example Borrower | C6: CM00000000EXAMP | D6: 32874 | E6: =IF(D6="","",DATEDIF(D6,TODAY(),"y")) -> 36 | F6: F | G6: +256 700 000000 | I6: Kampala | J6: Kampala (Head Office) | K6: Retail trader | L6: 1500000 | M6: B - Good | N6: 46037 | O6: Y | P6: Example Next of Kin | Q6: +256 700 000001 | R6: Spouse | S6: Example row — replace or delete.
E7: =IF(D7="","",DATEDIF(D7,TODAY(),"y"))
E8: =IF(D8="","",DATEDIF(D8,TODAY(),"y"))
E9: =IF(D9="","",DATEDIF(D9,TODAY(),"y"))
E10: =IF(D10="","",DATEDIF(D10,TODAY(),"y"))
E11: =IF(D11="","",DATEDIF(D11,TODAY(),"y"))
E12: =IF(D12="","",DATEDIF(D12,TODAY(),"y"))
E13: =IF(D13="","",DATEDIF(D13,TODAY(),"y"))
E14: =IF(D14="","",DATEDIF(D14,TODAY(),"y"))
E15: =IF(D15="","",DATEDIF(D15,TODAY(),"y"))
E16: =IF(D16="","",DATEDIF(D16,TODAY(),"y"))
E17: =IF(D17="","",DATEDIF(D17,TODAY(),"y"))
E18: =IF(D18="","",DATEDIF(D18,TODAY(),"y"))
... E55: =IF(D55="","",DATEDIF(D55,TODAY(),"y"))

Sheet GUARANTORS
A1: GUARANTORS | Guarantor Register
A2: Jopetnah International Limited | Version 1.0 | As at 01 Oct 2026 | Everyone standing surety for a loan, linked to the loan they guarantee
A4: Guarantor ID | B4: Full Name | C4: National ID | D4: Phone Number | E4: Address | F4: Related Loan ID | G4: Related Borrower | H4: Relationship to Borrower | I4: Guarantee Amount (UGX) | J4: Notes
A5: EXAMPLE | B5: Example Guarantor | C5: CM00000001EXAMP | D5: +256 700 000002 | E5: Kampala | F5: L-0001 | G5: =IFERROR(IF(F5="","",VLOOKUP(F5,PORTFOLIO!$A:$C,3,0)),"Loan ID not found") -> Example Borrower | H5: Sibling | I5: 2000000 | J5: Example row — replace or delete.
G6: =IFERROR(IF(F6="","",VLOOKUP(F6,PORTFOLIO!$A:$C,3,0)),"Loan ID not found")
G7: =IFERROR(IF(F7="","",VLOOKUP(F7,PORTFOLIO!$A:$C,3,0)),"Loan ID not found")
G8: =IFERROR(IF(F8="","",VLOOKUP(F8,PORTFOLIO!$A:$C,3,0)),"Loan ID not found")
G9: =IFERROR(IF(F9="","",VLOOKUP(F9,PORTFOLIO!$A:$C,3,0)),"Loan ID not found")
G10: =IFERROR(IF(F10="","",VLOOKUP(F10,PORTFOLIO!$A:$C,3,0)),"Loan ID not found")
G11: =IFERROR(IF(F11="","",VLOOKUP(F11,PORTFOLIO!$A:$C,3,0)),"Loan ID not found")
G12: =IFERROR(IF(F12="","",VLOOKUP(F12,PORTFOLIO!$A:$C,3,0)),"Loan ID not found")
G13: =IFERROR(IF(F13="","",VLOOKUP(F13,PORTFOLIO!$A:$C,3,0)),"Loan ID not found")
G14: =IFERROR(IF(F14="","",VLOOKUP(F14,PORTFOLIO!$A:$C,3,0)),"Loan ID not found")
G15: =IFERROR(IF(F15="","",VLOOKUP(F15,PORTFOLIO!$A:$C,3,0)),"Loan ID not found")
G16: =IFERROR(IF(F16="","",VLOOKUP(F16,PORTFOLIO!$A:$C,3,0)),"Loan ID not found")
G17: =IFERROR(IF(F17="","",VLOOKUP(F17,PORTFOLIO!$A:$C,3,0)),"Loan ID not found")
... G34: =IFERROR(IF(F34="","",VLOOKUP(F34,PORTFOLIO!$A:$C,3,0)),"Loan ID not found")

Sheet COLLATERAL
A1: COLLATERAL | Collateral Register
A2: Jopetnah International Limited | Version 1.0 | As at 01 Oct 2026 | Security pledged against loans, linked back to PORTFOLIO
A4: Collateral ID | B4: Related Loan ID | C4: Borrower Name | D4: Collateral Type | E4: Description | F4: Estimated Value (UGX) | G4: Valuation Date | H4: Valued By | I4: Location / Storage | J4: Status | K4: Notes
A5: EXAMPLE | B5: L-0001 | C5: =IFERROR(IF(B5="","",VLOOKUP(B5,PORTFOLIO!$A:$C,3,0)),"Loan ID not found") -> Example Borrower | D5: Household Goods / Chattels | E5: Household furniture and electronics | F5: 3000000 | G5: 46037 | H5: Loan Officer | I5: Kept with borrower | J5: Held | K5: Example row — replace or delete.
C6: =IFERROR(IF(B6="","",VLOOKUP(B6,PORTFOLIO!$A:$C,3,0)),"Loan ID not found")
C7: =IFERROR(IF(B7="","",VLOOKUP(B7,PORTFOLIO!$A:$C,3,0)),"Loan ID not found")
C8: =IFERROR(IF(B8="","",VLOOKUP(B8,PORTFOLIO!$A:$C,3,0)),"Loan ID not found")
C9: =IFERROR(IF(B9="","",VLOOKUP(B9,PORTFOLIO!$A:$C,3,0)),"Loan ID not found")
C10: =IFERROR(IF(B10="","",VLOOKUP(B10,PORTFOLIO!$A:$C,3,0)),"Loan ID not found")
C11: =IFERROR(IF(B11="","",VLOOKUP(B11,PORTFOLIO!$A:$C,3,0)),"Loan ID not found")
C12: =IFERROR(IF(B12="","",VLOOKUP(B12,PORTFOLIO!$A:$C,3,0)),"Loan ID not found")
C13: =IFERROR(IF(B13="","",VLOOKUP(B13,PORTFOLIO!$A:$C,3,0)),"Loan ID not found")
C14: =IFERROR(IF(B14="","",VLOOKUP(B14,PORTFOLIO!$A:$C,3,0)),"Loan ID not found")
C15: =IFERROR(IF(B15="","",VLOOKUP(B15,PORTFOLIO!$A:$C,3,0)),"Loan ID not found")
C16: =IFERROR(IF(B16="","",VLOOKUP(B16,PORTFOLIO!$A:$C,3,0)),"Loan ID not found")
C17: =IFERROR(IF(B17="","",VLOOKUP(B17,PORTFOLIO!$A:$C,3,0)),"Loan ID not found")
... C34: =IFERROR(IF(B34="","",VLOOKUP(B34,PORTFOLIO!$A:$C,3,0)),"Loan ID not found")

Sheet APPLICATIONS
A1: APPLICATIONS | Loan Application Register
A2: Jopetnah International Limited | Version 1.0 | As at 01 Oct 2026 | Every request received, from intake through to the approval decision
A3: Log every application here first. Once approved and disbursed, create the matching row in PORTFOLIO and record its Loan ID in "Linked Loan ID" so the two registers stay traceable to each other.
A5: Application ID | B5: Date Received | C5: Borrower Name | D5: Branch / Location | E5: Loan Product | F5: Amount Requested (UGX) | G5: Term Requested (Months) | H5: Purpose | I5: Loan Officer | J5: Status | K5: Approved Amount (UGX) | L5: Approved Term (Months) | M5: Approved By | N5: Decision Date | O5: Rejection Reason | P5: Linked Loan ID | Q5: Notes
A6: EXAMPLE | B6: 46027 | C6: Example Borrower | D6: Kampala (Head Office) | E6: Business Growth Loan | F6: 5000000 | G6: 12 | H6: Working capital | I6: Example Loan Officer | J6: Disbursed | K6: 5000000 | L6: 12 | M6: Managing Director | N6: 46032 | P6: L-0001 | Q6: Example row — replace or delete.

Sheet PORTFOLIO
A1: PORTFOLIO | Loan Portfolio Register (Master Ledger)
A2: Jopetnah International Limited | Version 1.0 | As at 01 Oct 2026 | The central record of every loan — one row per disbursed loan; everything else in the workbook rolls up from here
A3: Create one row here for every loan once disbursed. "Suggested Rate/Method" are read-only references pulled from PRODUCTS for the chosen Loan Product — the actual Interest Method and Rate fields next to them are independently editable, since real loans are sometimes negotiated away from the standard card. Outstanding Balance = Total Repayable − Total Paid to Date (the full remaining principal-plus-interest obligation under the original schedule, not a precise principal-only payoff figure — for an exact early-settlement figure, use the AMORT sheet). Arrears are estimated by comparing installments that should have fallen due by today against what has actually been paid; this assumes Monthly repayment frequency — for Weekly or Bi-Weekly loans, calculate arrears manually. The schedule generator on the AMORT sheet is capped at 60 installments (5 years monthly).
A5: Loan ID | B5: Application ID | C5: Borrower Name | D5: Branch / Location | E5: Loan Officer | F5: Loan Product | G5: Suggested Rate % (from Product) | H5: Suggested Method (from Product) | I5: Interest Method | J5: Interest Rate (% p.a.) | K5: Principal Amount (UGX) | L5: Term (Months) | M5: Repayment Frequency | N5: Disbursement Date | O5: First Repayment Date | P5: Maturity Date | Q5: Installment Amount (UGX) | R5: Total Interest (UGX) | S5: Total Repayable (UGX) | T5: Total Paid to Date (UGX) | U5: Outstanding Balance (UGX) | V5: Expected Installments Elapsed | W5: Arrears Amount (UGX) | X5: Days in Arrears | Y5: PAR Category | Z5: Status | AA5: Guarantor Ref | AB5: Collateral Ref | AC5: Notes
A6: L-0001 | B6: EXAMPLE | C6: Example Borrower | D6: Kampala (Head Office) | E6: Example Loan Officer | F6: Business Growth Loan | G6: =IFERROR(IF(F6="","",INDEX(PRODUCTS!$D$6:$D$17,MATCH(F6,PRODUCTS!$B$6:$B$17,0))),"Product not found") -> 24 | H6: =IFERROR(IF(F6="","",INDEX(PRODUCTS!$C$6:$C$17,MATCH(F6,PRODUCTS!$B$6:$B$17,0))),"Product not found") -> Reducing Balance | I6: Reducing Balance | J6: 24 | K6: 5000000 | L6: 12 | M6: Monthly | N6: 46037 | O6: 46068 | P6: =IF(OR(N6="",L6=""),"",EDATE(N6,L6)) -> 46402 | Q6: =IF(OR(K6="",J6="",L6="",L6=0),"",IF(I6="Flat Rate",(K6+K6*J6/100*L6/12)/L6,PMT(J6/1200,L6,-K6))) -> 472797.98 | R6: =IF(OR(S6="",K6=""),"",S6-K6) -> 673575.8 | S6: =IF(OR(Q6="",L6=""),"",Q6*L6) -> 5673575.8 | T6: =IF(A6="","",SUMIFS(REPAYMENTS!$F$5:$F$104,REPAYMENTS!$C$5:$C$104,A6)) -> 470735 | U6: =IF(OR(S6="",T6=""),"",MAX(0,S6-T6)) -> 5202840.8 | V6: =IF(OR(O6="",L6=""),"",IF(TODAY()<O6,0,MIN(L6,DATEDIF(O6,TODAY(),"m")+1))) -> 8 | W6: =IF(OR(V6="",Q6="",T6=""),"",MAX(0,V6*Q6-T6)) -> 3311648.9 | X6: =IF(OR(W6="",V6=""),"",IF(OR(W6<=0,Z6="Fully Paid",Z6="Written Off"),0,TODAY()-EDATE(O6,V6-1))) -> 17 | Y6: =IF(A6="","",IF(Z6="Written Off","Written Off",IF(OR(X6="",X6=0),"Current",IF(X6<=30,"1-30 Days",IF(X6<=60,"31-60 Days",IF(X6<=90,"61-90 Days","90+ Days (PAR90)")))))) -> 1-30 Days | Z6: Active | AC6: Example row — replace or delete. Loan ID kept as L-0001 so GUARANTORS/COLLATERAL example rows still resolve.
G7: =IFERROR(IF(F7="","",INDEX(PRODUCTS!$D$6:$D$17,MATCH(F7,PRODUCTS!$B$6:$B$17,0))),"Product not found") | H7: =IFERROR(IF(F7="","",INDEX(PRODUCTS!$C$6:$C$17,MATCH(F7,PRODUCTS!$B$6:$B$17,0))),"Product not found") | P7: =IF(OR(N7="",L7=""),"",EDATE(N7,L7)) | Q7: =IF(OR(K7="",J7="",L7="",L7=0),"",IF(I7="Flat Rate",(K7+K7*J7/100*L7/12)/L7,PMT(J7/1200,L7,-K7))) | R7: =IF(OR(S7="",K7=""),"",S7-K7) | S7: =IF(OR(Q7="",L7=""),"",Q7*L7) | T7: =IF(A7="","",SUMIFS(REPAYMENTS!$F$5:$F$104,REPAYMENTS!$C$5:$C$104,A7)) | U7: =IF(OR(S7="",T7=""),"",MAX(0,S7-T7)) | V7: =IF(OR(O7="",L7=""),"",IF(TODAY()<O7,0,MIN(L7,DATEDIF(O7,TODAY(),"m")+1))) | W7: =IF(OR(V7="",Q7="",T7=""),"",MAX(0,V7*Q7-T7)) | X7: =IF(OR(W7="",V7=""),"",IF(OR(W7<=0,Z7="Fully Paid",Z7="Written Off"),0,TODAY()-EDATE(O7,V7-1))) | Y7: =IF(A7="","",IF(Z7="Written Off","Written Off",IF(OR(X7="",X7=0),"Current",IF(X7<=30,"1-30 Days",IF(X7<=60,"31-60 Days",IF(X7<=90,"61-90 Days","90+ Days (PAR90)"))))))
G8: =IFERROR(IF(F8="","",INDEX(PRODUCTS!$D$6:$D$17,MATCH(F8,PRODUCTS!$B$6:$B$17,0))),"Product not found") | H8: =IFERROR(IF(F8="","",INDEX(PRODUCTS!$C$6:$C$17,MATCH(F8,PRODUCTS!$B$6:$B$17,0))),"Product not found") | P8: =IF(OR(N8="",L8=""),"",EDATE(N8,L8)) | Q8: =IF(OR(K8="",J8="",L8="",L8=0),"",IF(I8="Flat Rate",(K8+K8*J8/100*L8/12)/L8,PMT(J8/1200,L8,-K8))) | R8: =IF(OR(S8="",K8=""),"",S8-K8) | S8: =IF(OR(Q8="",L8=""),"",Q8*L8) | T8: =IF(A8="","",SUMIFS(REPAYMENTS!$F$5:$F$104,REPAYMENTS!$C$5:$C$104,A8)) | U8: =IF(OR(S8="",T8=""),"",MAX(0,S8-T8)) | V8: =IF(OR(O8="",L8=""),"",IF(TODAY()<O8,0,MIN(L8,DATEDIF(O8,TODAY(),"m")+1))) | W8: =IF(OR(V8="",Q8="",T8=""),"",MAX(0,V8*Q8-T8)) | X8: =IF(OR(W8="",V8=""),"",IF(OR(W8<=0,Z8="Fully Paid",Z8="Written Off"),0,TODAY()-EDATE(O8,V8-1))) | Y8: =IF(A8="","",IF(Z8="Written Off","Written Off",IF(OR(X8="",X8=0),"Current",IF(X8<=30,"1-30 Days",IF(X8<=60,"31-60 Days",IF(X8<=90,"61-90 Days","90+ Days (PAR90)"))))))
G9: =IFERROR(IF(F9="","",INDEX(PRODUCTS!$D$6:$D$17,MATCH(F9,PRODUCTS!$B$6:$B$17,0))),"Product not found") | H9: =IFERROR(IF(F9="","",INDEX(PRODUCTS!$C$6:$C$17,MATCH(F9,PRODUCTS!$B$6:$B$17,0))),"Product not found") | P9: =IF(OR(N9="",L9=""),"",EDATE(N9,L9)) | Q9: =IF(OR(K9="",J9="",L9="",L9=0),"",IF(I9="Flat Rate",(K9+K9*J9/100*L9/12)/L9,PMT(J9/1200,L9,-K9))) | R9: =IF(OR(S9="",K9=""),"",S9-K9) | S9: =IF(OR(Q9="",L9=""),"",Q9*L9) | T9: =IF(A9="","",SUMIFS(REPAYMENTS!$F$5:$F$104,REPAYMENTS!$C$5:$C$104,A9)) | U9: =IF(OR(S9="",T9=""),"",MAX(0,S9-T9)) | V9: =IF(OR(O9="",L9=""),"",IF(TODAY()<O9,0,MIN(L9,DATEDIF(O9,TODAY(),"m")+1))) | W9: =IF(OR(V9="",Q9="",T9=""),"",MAX(0,V9*Q9-T9)) | X9: =IF(OR(W9="",V9=""),"",IF(OR(W9<=0,Z9="Fully Paid",Z9="Written Off"),0,TODAY()-EDATE(O9,V9-1))) | Y9: =IF(A9="","",IF(Z9="Written Off","Written Off",IF(OR(X9="",X9=0),"Current",IF(X9<=30,"1-30 Days",IF(X9<=60,"31-60 Days",IF(X9<=90,"61-90 Days","90+ Days (PAR90)"))))))
G10: =IFERROR(IF(F10="","",INDEX(PRODUCTS!$D$6:$D$17,MATCH(F10,PRODUCTS!$B$6:$B$17,0))),"Product not found") | H10: =IFERROR(IF(F10="","",INDEX(PRODUCTS!$C$6:$C$17,MATCH(F10,PRODUCTS!$B$6:$B$17,0))),"Product not found") | P10: =IF(OR(N10="",L10=""),"",EDATE(N10,L10)) | Q10: =IF(OR(K10="",J10="",L10="",L10=0),"",IF(I10="Flat Rate",(K10+K10*J10/100*L10/12)/L10,PMT(J10/1200,L10,-K10))) | R10: =IF(OR(S10="",K10=""),"",S10-K10) | S10: =IF(OR(Q10="",L10=""),"",Q10*L10) | T10: =IF(A10="","",SUMIFS(REPAYMENTS!$F$5:$F$104,REPAYMENTS!$C$5:$C$104,A10)) | U10: =IF(OR(S10="",T10=""),"",MAX(0,S10-T10)) | V10: =IF(OR(O10="",L10=""),"",IF(TODAY()<O10,0,MIN(L10,DATEDIF(O10,TODAY(),"m")+1))) | W10: =IF(OR(V10="",Q10="",T10=""),"",MAX(0,V10*Q10-T10)) | X10: =IF(OR(W10="",V10=""),"",IF(OR(W10<=0,Z10="Fully Paid",Z10="Written Off"),0,TODAY()-EDATE(O10,V10-1))) | Y10: =IF(A10="","",IF(Z10="Written Off","Written Off",IF(OR(X10="",X10=0),"Current",IF(X10<=30,"1-30 Days",IF(X10<=60,"31-60 Days",IF(X10<=90,"61-90 Days","90+ Days (PAR90)"))))))
G11: =IFERROR(IF(F11="","",INDEX(PRODUCTS!$D$6:$D$17,MATCH(F11,PRODUCTS!$B$6:$B$17,0))),"Product not found") | H11: =IFERROR(IF(F11="","",INDEX(PRODUCTS!$C$6:$C$17,MATCH(F11,PRODUCTS!$B$6:$B$17,0))),"Product not found") | P11: =IF(OR(N11="",L11=""),"",EDATE(N11,L11)) | Q11: =IF(OR(K11="",J11="",L11="",L11=0),"",IF(I11="Flat Rate",(K11+K11*J11/100*L11/12)/L11,PMT(J11/1200,L11,-K11))) | R11: =IF(OR(S11="",K11=""),"",S11-K11) | S11: =IF(OR(Q11="",L11=""),"",Q11*L11) | T11: =IF(A11="","",SUMIFS(REPAYMENTS!$F$5:$F$104,REPAYMENTS!$C$5:$C$104,A11)) | U11: =IF(OR(S11="",T11=""),"",MAX(0,S11-T11)) | V11: =IF(OR(O11="",L11=""),"",IF(TODAY()<O11,0,MIN(L11,DATEDIF(O11,TODAY(),"m")+1))) | W11: =IF(OR(V11="",Q11="",T11=""),"",MAX(0,V11*Q11-T11)) | X11: =IF(OR(W11="",V11=""),"",IF(OR(W11<=0,Z11="Fully Paid",Z11="Written Off"),0,TODAY()-EDATE(O11,V11-1))) | Y11: =IF(A11="","",IF(Z11="Written Off","Written Off",IF(OR(X11="",X11=0),"Current",IF(X11<=30,"1-30 Days",IF(X11<=60,"31-60 Days",IF(X11<=90,"61-90 Days","90+ Days (PAR90)"))))))
G12: =IFERROR(IF(F12="","",INDEX(PRODUCTS!$D$6:$D$17,MATCH(F12,PRODUCTS!$B$6:$B$17,0))),"Product not found") | H12: =IFERROR(IF(F12="","",INDEX(PRODUCTS!$C$6:$C$17,MATCH(F12,PRODUCTS!$B$6:$B$17,0))),"Product not found") | P12: =IF(OR(N12="",L12=""),"",EDATE(N12,L12)) | Q12: =IF(OR(K12="",J12="",L12="",L12=0),"",IF(I12="Flat Rate",(K12+K12*J12/100*L12/12)/L12,PMT(J12/1200,L12,-K12))) | R12: =IF(OR(S12="",K12=""),"",S12-K12) | S12: =IF(OR(Q12="",L12=""),"",Q12*L12) | T12: =IF(A12="","",SUMIFS(REPAYMENTS!$F$5:$F$104,REPAYMENTS!$C$5:$C$104,A12)) | U12: =IF(OR(S12="",T12=""),"",MAX(0,S12-T12)) | V12: =IF(OR(O12="",L12=""),"",IF(TODAY()<O12,0,MIN(L12,DATEDIF(O12,TODAY(),"m")+1))) | W12: =IF(OR(V12="",Q12="",T12=""),"",MAX(0,V12*Q12-T12)) | X12: =IF(OR(W12="",V12=""),"",IF(OR(W12<=0,Z12="Fully Paid",Z12="Written Off"),0,TODAY()-EDATE(O12,V12-1))) | Y12: =IF(A12="","",IF(Z12="Written Off","Written Off",IF(OR(X12="",X12=0),"Current",IF(X12<=30,"1-30 Days",IF(X12<=60,"31-60 Days",IF(X12<=90,"61-90 Days","90+ Days (PAR90)"))))))
G13: =IFERROR(IF(F13="","",INDEX(PRODUCTS!$D$6:$D$17,MATCH(F13,PRODUCTS!$B$6:$B$17,0))),"Product not found") | H13: =IFERROR(IF(F13="","",INDEX(PRODUCTS!$C$6:$C$17,MATCH(F13,PRODUCTS!$B$6:$B$17,0))),"Product not found") | P13: =IF(OR(N13="",L13=""),"",EDATE(N13,L13)) | Q13: =IF(OR(K13="",J13="",L13="",L13=0),"",IF(I13="Flat Rate",(K13+K13*J13/100*L13/12)/L13,PMT(J13/1200,L13,-K13))) | R13: =IF(OR(S13="",K13=""),"",S13-K13) | S13: =IF(OR(Q13="",L13=""),"",Q13*L13) | T13: =IF(A13="","",SUMIFS(REPAYMENTS!$F$5:$F$104,REPAYMENTS!$C$5:$C$104,A13)) | U13: =IF(OR(S13="",T13=""),"",MAX(0,S13-T13)) | V13: =IF(OR(O13="",L13=""),"",IF(TODAY()<O13,0,MIN(L13,DATEDIF(O13,TODAY(),"m")+1))) | W13: =IF(OR(V13="",Q13="",T13=""),"",MAX(0,V13*Q13-T13)) | X13: =IF(OR(W13="",V13=""),"",IF(OR(W13<=0,Z13="Fully Paid",Z13="Written Off"),0,TODAY()-EDATE(O13,V13-1))) | Y13: =IF(A13="","",IF(Z13="Written Off","Written Off",IF(OR(X13="",X13=0),"Current",IF(X13<=30,"1-30 Days",IF(X13<=60,"31-60 Days",IF(X13<=90,"61-90 Days","90+ Days (PAR90)"))))))
G14: =IFERROR(IF(F14="","",INDEX(PRODUCTS!$D$6:$D$17,MATCH(F14,PRODUCTS!$B$6:$B$17,0))),"Product not found") | H14: =IFERROR(IF(F14="","",INDEX(PRODUCTS!$C$6:$C$17,MATCH(F14,PRODUCTS!$B$6:$B$17,0))),"Product not found") | P14: =IF(OR(N14="",L14=""),"",EDATE(N14,L14)) | Q14: =IF(OR(K14="",J14="",L14="",L14=0),"",IF(I14="Flat Rate",(K14+K14*J14/100*L14/12)/L14,PMT(J14/1200,L14,-K14))) | R14: =IF(OR(S14="",K14=""),"",S14-K14) | S14: =IF(OR(Q14="",L14=""),"",Q14*L14) | T14: =IF(A14="","",SUMIFS(REPAYMENTS!$F$5:$F$104,REPAYMENTS!$C$5:$C$104,A14)) | U14: =IF(OR(S14="",T14=""),"",MAX(0,S14-T14)) | V14: =IF(OR(O14="",L14=""),"",IF(TODAY()<O14,0,MIN(L14,DATEDIF(O14,TODAY(),"m")+1))) | W14: =IF(OR(V14="",Q14="",T14=""),"",MAX(0,V14*Q14-T14)) | X14: =IF(OR(W14="",V14=""),"",IF(OR(W14<=0,Z14="Fully Paid",Z14="Written Off"),0,TODAY()-EDATE(O14,V14-1))) | Y14: =IF(A14="","",IF(Z14="Written Off","Written Off",IF(OR(X14="",X14=0),"Current",IF(X14<=30,"1-30 Days",IF(X14<=60,"31-60 Days",IF(X14<=90,"61-90 Days","90+ Days (PAR90)"))))))
G15: =IFERROR(IF(F15="","",INDEX(PRODUCTS!$D$6:$D$17,MATCH(F15,PRODUCTS!$B$6:$B$17,0))),"Product not found") | H15: =IFERROR(IF(F15="","",INDEX(PRODUCTS!$C$6:$C$17,MATCH(F15,PRODUCTS!$B$6:$B$17,0))),"Product not found") | P15: =IF(OR(N15="",L15=""),"",EDATE(N15,L15)) | Q15: =IF(OR(K15="",J15="",L15="",L15=0),"",IF(I15="Flat Rate",(K15+K15*J15/100*L15/12)/L15,PMT(J15/1200,L15,-K15))) | R15: =IF(OR(S15="",K15=""),"",S15-K15) | S15: =IF(OR(Q15="",L15=""),"",Q15*L15) | T15: =IF(A15="","",SUMIFS(REPAYMENTS!$F$5:$F$104,REPAYMENTS!$C$5:$C$104,A15)) | U15: =IF(OR(S15="",T15=""),"",MAX(0,S15-T15)) | V15: =IF(OR(O15="",L15=""),"",IF(TODAY()<O15,0,MIN(L15,DATEDIF(O15,TODAY(),"m")+1))) | W15: =IF(OR(V15="",Q15="",T15=""),"",MAX(0,V15*Q15-T15)) | X15: =IF(OR(W15="",V15=""),"",IF(OR(W15<=0,Z15="Fully Paid",Z15="Written Off"),0,TODAY()-EDATE(O15,V15-1))) | Y15: =IF(A15="","",IF(Z15="Written Off","Written Off",IF(OR(X15="",X15=0),"Current",IF(X15<=30,"1-30 Days",IF(X15<=60,"31-60 Days",IF(X15<=90,"61-90 Days","90+ Days (PAR90)"))))))
G16: =IFERROR(IF(F16="","",INDEX(PRODUCTS!$D$6:$D$17,MATCH(F16,PRODUCTS!$B$6:$B$17,0))),"Product not found") | H16: =IFERROR(IF(F16="","",INDEX(PRODUCTS!$C$6:$C$17,MATCH(F16,PRODUCTS!$B$6:$B$17,0))),"Product not found") | P16: =IF(OR(N16="",L16=""),"",EDATE(N16,L16)) | Q16: =IF(OR(K16="",J16="",L16="",L16=0),"",IF(I16="Flat Rate",(K16+K16*J16/100*L16/12)/L16,PMT(J16/1200,L16,-K16))) | R16: =IF(OR(S16="",K16=""),"",S16-K16) | S16: =IF(OR(Q16="",L16=""),"",Q16*L16) | T16: =IF(A16="","",SUMIFS(REPAYMENTS!$F$5:$F$104,REPAYMENTS!$C$5:$C$104,A16)) | U16: =IF(OR(S16="",T16=""),"",MAX(0,S16-T16)) | V16: =IF(OR(O16="",L16=""),"",IF(TODAY()<O16,0,MIN(L16,DATEDIF(O16,TODAY(),"m")+1))) | W16: =IF(OR(V16="",Q16="",T16=""),"",MAX(0,V16*Q16-T16)) | X16: =IF(OR(W16="",V16=""),"",IF(OR(W16<=0,Z16="Fully Paid",Z16="Written Off"),0,TODAY()-EDATE(O16,V16-1))) | Y16: =IF(A16="","",IF(Z16="Written Off","Written Off",IF(OR(X16="",X16=0),"Current",IF(X16<=30,"1-30 Days",IF(X16<=60,"31-60 Days",IF(X16<=90,"61-90 Days","90+ Days (PAR90)"))))))
G17: =IFERROR(IF(F17="","",INDEX(PRODUCTS!$D$6:$D$17,MATCH(F17,PRODUCTS!$B$6:$B$17,0))),"Product not found") | H17: =IFERROR(IF(F17="","",INDEX(PRODUCTS!$C$6:$C$17,MATCH(F17,PRODUCTS!$B$6:$B$17,0))),"Product not found") | P17: =IF(OR(N17="",L17=""),"",EDATE(N17,L17)) | Q17: =IF(OR(K17="",J17="",L17="",L17=0),"",IF(I17="Flat Rate",(K17+K17*J17/100*L17/12)/L17,PMT(J17/1200,L17,-K17))) | R17: =IF(OR(S17="",K17=""),"",S17-K17) | S17: =IF(OR(Q17="",L17=""),"",Q17*L17) | T17: =IF(A17="","",SUMIFS(REPAYMENTS!$F$5:$F$104,REPAYMENTS!$C$5:$C$104,A17)) | U17: =IF(OR(S17="",T17=""),"",MAX(0,S17-T17)) | V17: =IF(OR(O17="",L17=""),"",IF(TODAY()<O17,0,MIN(L17,DATEDIF(O17,TODAY(),"m")+1))) | W17: =IF(OR(V17="",Q17="",T17=""),"",MAX(0,V17*Q17-T17)) | X17: =IF(OR(W17="",V17=""),"",IF(OR(W17<=0,Z17="Fully Paid",Z17="Written Off"),0,TODAY()-EDATE(O17,V17-1))) | Y17: =IF(A17="","",IF(Z17="Written Off","Written Off",IF(OR(X17="",X17=0),"Current",IF(X17<=30,"1-30 Days",IF(X17<=60,"31-60 Days",IF(X17<=90,"61-90 Days","90+ Days (PAR90)"))))))
G18: =IFERROR(IF(F18="","",INDEX(PRODUCTS!$D$6:$D$17,MATCH(F18,PRODUCTS!$B$6:$B$17,0))),"Product not found") | H18: =IFERROR(IF(F18="","",INDEX(PRODUCTS!$C$6:$C$17,MATCH(F18,PRODUCTS!$B$6:$B$17,0))),"Product not found") | P18: =IF(OR(N18="",L18=""),"",EDATE(N18,L18)) | Q18: =IF(OR(K18="",J18="",L18="",L18=0),"",IF(I18="Flat Rate",(K18+K18*J18/100*L18/12)/L18,PMT(J18/1200,L18,-K18))) | R18: =IF(OR(S18="",K18=""),"",S18-K18) | S18: =IF(OR(Q18="",L18=""),"",Q18*L18) | T18: =IF(A18="","",SUMIFS(REPAYMENTS!$F$5:$F$104,REPAYMENTS!$C$5:$C$104,A18)) | U18: =IF(OR(S18="",T18=""),"",MAX(0,S18-T18)) | V18: =IF(OR(O18="",L18=""),"",IF(TODAY()<O18,0,MIN(L18,DATEDIF(O18,TODAY(),"m")+1))) | W18: =IF(OR(V18="",Q18="",T18=""),"",MAX(0,V18*Q18-T18)) | X18: =IF(OR(W18="",V18=""),"",IF(OR(W18<=0,Z18="Fully Paid",Z18="Written Off"),0,TODAY()-EDATE(O18,V18-1))) | Y18: =IF(A18="","",IF(Z18="Written Off","Written Off",IF(OR(X18="",X18=0),"Current",IF(X18<=30,"1-30 Days",IF(X18<=60,"31-60 Days",IF(X18<=90,"61-90 Days","90+ Days (PAR90)"))))))
... G55: =IFERROR(IF(F55="","",INDEX(PRODUCTS!$D$6:$D$17,MATCH(F55,PRODUCTS!$B$6:$B$17,0))),"Product not found") | H55: =IFERROR(IF(F55="","",INDEX(PRODUCTS!$C$6:$C$17,MATCH(F55,PRODUCTS!$B$6:$B$17,0))),"Product not found") | P55: =IF(OR(N55="",L55=""),"",EDATE(N55,L55)) | Q55: =IF(OR(K55="",J55="",L55="",L55=0),"",IF(I55="Flat Rate",(K55+K55*J55/100*L55/12)/L55,PMT(J55/1200,L55,-K55))) | R55: =IF(OR(S55="",K55=""),"",S55-K55) | S55: =IF(OR(Q55="",L55=""),"",Q55*L55) | T55: =IF(A55="","",SUMIFS(REPAYMENTS!$F$5:$F$104,REPAYMENTS!$C$5:$C$104,A55)) | U55: =IF(OR(S55="",T55=""),"",MAX(0,S55-T55)) | V55: =IF(OR(O55="",L55=""),"",IF(TODAY()<O55,0,MIN(L55,DATEDIF(O55,TODAY(),"m")+1))) | W55: =IF(OR(V55="",Q55="",T55=""),"",MAX(0,V55*Q55-T55)) | X55: =IF(OR(W55="",V55=""),"",IF(OR(W55<=0,Z55="Fully Paid",Z55="Written Off"),0,TODAY()-EDATE(O55,V55-1))) | Y55: =IF(A55="","",IF(Z55="Written Off","Written Off",IF(OR(X55="",X55=0),"Current",IF(X55<=30,"1-30 Days",IF(X55<=60,"31-60 Days",IF(X55<=90,"61-90 Days","90+ Days (PAR90)"))))))

Sheet REPAYMENTS
A1: REPAYMENTS | Repayment / Collections Register
A2: Jopetnah International Limited | Version 1.0 | As at 01 Oct 2026 | Every payment received against a loan — PORTFOLIO totals roll up from here
A4: Payment ID | B4: Date | C4: Loan ID | D4: Borrower Name | E4: Loan Officer | F4: Amount Paid (UGX) | G4: Payment Method | H4: Receipt No. | I4: Received By | J4: Notes
A5: EXAMPLE | B5: 46068 | C5: L-0001 | D5: =IFERROR(IF(C5="","",VLOOKUP(C5,PORTFOLIO!$A:$C,3,0)),"Loan ID not found") -> Example Borrower | E5: =IFERROR(IF(C5="","",VLOOKUP(C5,PORTFOLIO!$A:$E,5,0)),"Loan ID not found") -> Example Loan Officer | F5: 470735 | G5: Mobile Money | H5: RCT-0001 | I5: Example Loan Officer | J5: Example row — replace or delete.
D6: =IFERROR(IF(C6="","",VLOOKUP(C6,PORTFOLIO!$A:$C,3,0)),"Loan ID not found") | E6: =IFERROR(IF(C6="","",VLOOKUP(C6,PORTFOLIO!$A:$E,5,0)),"Loan ID not found")
D7: =IFERROR(IF(C7="","",VLOOKUP(C7,PORTFOLIO!$A:$C,3,0)),"Loan ID not found") | E7: =IFERROR(IF(C7="","",VLOOKUP(C7,PORTFOLIO!$A:$E,5,0)),"Loan ID not found")
D8: =IFERROR(IF(C8="","",VLOOKUP(C8,PORTFOLIO!$A:$C,3,0)),"Loan ID not found") | E8: =IFERROR(IF(C8="","",VLOOKUP(C8,PORTFOLIO!$A:$E,5,0)),"Loan ID not found")
D9: =IFERROR(IF(C9="","",VLOOKUP(C9,PORTFOLIO!$A:$C,3,0)),"Loan ID not found") | E9: =IFERROR(IF(C9="","",VLOOKUP(C9,PORTFOLIO!$A:$E,5,0)),"Loan ID not found")
D10: =IFERROR(IF(C10="","",VLOOKUP(C10,PORTFOLIO!$A:$C,3,0)),"Loan ID not found") | E10: =IFERROR(IF(C10="","",VLOOKUP(C10,PORTFOLIO!$A:$E,5,0)),"Loan ID not found")
D11: =IFERROR(IF(C11="","",VLOOKUP(C11,PORTFOLIO!$A:$C,3,0)),"Loan ID not found") | E11: =IFERROR(IF(C11="","",VLOOKUP(C11,PORTFOLIO!$A:$E,5,0)),"Loan ID not found")
D12: =IFERROR(IF(C12="","",VLOOKUP(C12,PORTFOLIO!$A:$C,3,0)),"Loan ID not found") | E12: =IFERROR(IF(C12="","",VLOOKUP(C12,PORTFOLIO!$A:$E,5,0)),"Loan ID not found")
D13: =IFERROR(IF(C13="","",VLOOKUP(C13,PORTFOLIO!$A:$C,3,0)),"Loan ID not found") | E13: =IFERROR(IF(C13="","",VLOOKUP(C13,PORTFOLIO!$A:$E,5,0)),"Loan ID not found")
D14: =IFERROR(IF(C14="","",VLOOKUP(C14,PORTFOLIO!$A:$C,3,0)),"Loan ID not found") | E14: =IFERROR(IF(C14="","",VLOOKUP(C14,PORTFOLIO!$A:$E,5,0)),"Loan ID not found")
D15: =IFERROR(IF(C15="","",VLOOKUP(C15,PORTFOLIO!$A:$C,3,0)),"Loan ID not found") | E15: =IFERROR(IF(C15="","",VLOOKUP(C15,PORTFOLIO!$A:$E,5,0)),"Loan ID not found")
D16: =IFERROR(IF(C16="","",VLOOKUP(C16,PORTFOLIO!$A:$C,3,0)),"Loan ID not found") | E16: =IFERROR(IF(C16="","",VLOOKUP(C16,PORTFOLIO!$A:$E,5,0)),"Loan ID not found")
D17: =IFERROR(IF(C17="","",VLOOKUP(C17,PORTFOLIO!$A:$C,3,0)),"Loan ID not found") | E17: =IFERROR(IF(C17="","",VLOOKUP(C17,PORTFOLIO!$A:$E,5,0)),"Loan ID not found")
... D104: =IFERROR(IF(C104="","",VLOOKUP(C104,PORTFOLIO!$A:$C,3,0)),"Loan ID not found") | E104: =IFERROR(IF(C104="","",VLOOKUP(C104,PORTFOLIO!$A:$E,5,0)),"Loan ID not found")

Sheet ARREARS-PAR
A1: ARREARS-PAR | Arrears & Portfolio-at-Risk (PAR) Report
A2: Jopetnah International Limited | Version 1.0 | As at 01 Oct 2026 | Risk Management — aging analysis of the live loan book
A3: Standard microfinance PAR methodology. "Live Portfolio Outstanding" below is the sum of the first five buckets (Current through 90+ Days) — written-off loans are excluded from that denominator, as they are no longer part of the active book.
A5: Ageing Bucket | B5: No. of Loans | C5: Outstanding Amount (UGX) | D5: % of Live Portfolio
A6: Current | B6: =COUNTIFS(PORTFOLIO!$Y$6:$Y$55,"Current",PORTFOLIO!$B$6:$B$55,"<>EXAMPLE") -> 0 | C6: =SUMIFS(PORTFOLIO!$U$6:$U$55,PORTFOLIO!$Y$6:$Y$55,"Current",PORTFOLIO!$B$6:$B$55,"<>EXAMPLE") -> 0 | D6: =IF(SUM(C6:C10)=0,"",C6/SUM(C6:C10))
A7: 1-30 Days | B7: =COUNTIFS(PORTFOLIO!$Y$6:$Y$55,"1-30 Days",PORTFOLIO!$B$6:$B$55,"<>EXAMPLE") -> 0 | C7: =SUMIFS(PORTFOLIO!$U$6:$U$55,PORTFOLIO!$Y$6:$Y$55,"1-30 Days",PORTFOLIO!$B$6:$B$55,"<>EXAMPLE") -> 0 | D7: =IF(SUM(C6:C10)=0,"",C7/SUM(C6:C10))
A8: 31-60 Days | B8: =COUNTIFS(PORTFOLIO!$Y$6:$Y$55,"31-60 Days",PORTFOLIO!$B$6:$B$55,"<>EXAMPLE") -> 0 | C8: =SUMIFS(PORTFOLIO!$U$6:$U$55,PORTFOLIO!$Y$6:$Y$55,"31-60 Days",PORTFOLIO!$B$6:$B$55,"<>EXAMPLE") -> 0 | D8: =IF(SUM(C6:C10)=0,"",C8/SUM(C6:C10))
A9: 61-90 Days | B9: =COUNTIFS(PORTFOLIO!$Y$6:$Y$55,"61-90 Days",PORTFOLIO!$B$6:$B$55,"<>EXAMPLE") -> 0 | C9: =SUMIFS(PORTFOLIO!$U$6:$U$55,PORTFOLIO!$Y$6:$Y$55,"61-90 Days",PORTFOLIO!$B$6:$B$55,"<>EXAMPLE") -> 0 | D9: =IF(SUM(C6:C10)=0,"",C9/SUM(C6:C10))
A10: 90+ Days (PAR90) | B10: =COUNTIFS(PORTFOLIO!$Y$6:$Y$55,"90+ Days (PAR90)",PORTFOLIO!$B$6:$B$55,"<>EXAMPLE") -> 0 | C10: =SUMIFS(PORTFOLIO!$U$6:$U$55,PORTFOLIO!$Y$6:$Y$55,"90+ Days (PAR90)",PORTFOLIO!$B$6:$B$55,"<>EXAMPLE") -> 0 | D10: =IF(SUM(C6:C10)=0,"",C10/SUM(C6:C10))
A11: Written Off | B11: =COUNTIFS(PORTFOLIO!$Y$6:$Y$55,"Written Off",PORTFOLIO!$B$6:$B$55,"<>EXAMPLE") -> 0 | C11: =SUMIFS(PORTFOLIO!$U$6:$U$55,PORTFOLIO!$Y$6:$Y$55,"Written Off",PORTFOLIO!$B$6:$B$55,"<>EXAMPLE") -> 0 | D11: =""
A13: Live Portfolio Outstanding (UGX) | B13: =SUM(C6:C10) -> 0
A14: Number of Loans in Arrears (1+ Days) | B14: =SUM(B7:B10) -> 0
A15: Total Arrears Amount (UGX) | B15: =SUMIFS(PORTFOLIO!$W$6:$W$55,PORTFOLIO!$B$6:$B$55,"<>EXAMPLE") -> 0
A16: PAR > 30 Days (%) | B16: =IF(SUM(C6:C10)=0,"",SUM(C8:C10)/SUM(C6:C10))
A17: PAR > 90 Days (%) | B17: =IF(SUM(C6:C10)=0,"",C10/SUM(C6:C10))

Sheet OFFICER-PERF
A1: OFFICER-PERF | Loan Officer Performance
A2: Jopetnah International Limited | Version 1.0 | As at 01 Oct 2026 | Type each officer's name once below — every metric calculates from PORTFOLIO and REPAYMENTS
A4: Loan Officer | B4: No. of Loans | C4: Total Disbursed (UGX) | D4: Total Outstanding (UGX) | E4: No. in Arrears | F4: PAR > 30 (%) | G4: Total Collected (UGX) | H4: Average Loan Size (UGX)
A5: Example Loan Officer | B5: =IF(A5="","",COUNTIF(PORTFOLIO!$E$6:$E$55,A5)) -> 1 | C5: =IF(A5="","",SUMIF(PORTFOLIO!$E$6:$E$55,A5,PORTFOLIO!$K$6:$K$55)) -> 5000000 | D5: =IF(A5="","",SUMIF(PORTFOLIO!$E$6:$E$55,A5,PORTFOLIO!$U$6:$U$55)) -> 5202840.8 | E5: =IF(A5="","",COUNTIFS(PORTFOLIO!$E$6:$E$55,A5,PORTFOLIO!$W$6:$W$55,">0")) -> 1 | F5: =IF(OR(A5="",D5=0,D5=""),"",(SUMIFS(PORTFOLIO!$U$6:$U$55,PORTFOLIO!$E$6:$E$55,A5,PORTFOLIO!$X$6:$X$55,">30"))/D5) -> 0 | G5: =IF(A5="","",SUMIF(REPAYMENTS!$E$5:$E$104,A5,REPAYMENTS!$F$5:$F$104)) -> 470735 | H5: =IF(OR(A5="",B5=0,B5=""),"",C5/B5) -> 5000000
B6: =IF(A6="","",COUNTIF(PORTFOLIO!$E$6:$E$55,A6)) | C6: =IF(A6="","",SUMIF(PORTFOLIO!$E$6:$E$55,A6,PORTFOLIO!$K$6:$K$55)) | D6: =IF(A6="","",SUMIF(PORTFOLIO!$E$6:$E$55,A6,PORTFOLIO!$U$6:$U$55)) | E6: =IF(A6="","",COUNTIFS(PORTFOLIO!$E$6:$E$55,A6,PORTFOLIO!$W$6:$W$55,">0")) | F6: =IF(OR(A6="",D6=0,D6=""),"",(SUMIFS(PORTFOLIO!$U$6:$U$55,PORTFOLIO!$E$6:$E$55,A6,PORTFOLIO!$X$6:$X$55,">30"))/D6) | G6: =IF(A6="","",SUMIF(REPAYMENTS!$E$5:$E$104,A6,REPAYMENTS!$F$5:$F$104)) | H6: =IF(OR(A6="",B6=0,B6=""),"",C6/B6)
B7: =IF(A7="","",COUNTIF(PORTFOLIO!$E$6:$E$55,A7)) | C7: =IF(A7="","",SUMIF(PORTFOLIO!$E$6:$E$55,A7,PORTFOLIO!$K$6:$K$55)) | D7: =IF(A7="","",SUMIF(PORTFOLIO!$E$6:$E$55,A7,PORTFOLIO!$U$6:$U$55)) | E7: =IF(A7="","",COUNTIFS(PORTFOLIO!$E$6:$E$55,A7,PORTFOLIO!$W$6:$W$55,">0")) | F7: =IF(OR(A7="",D7=0,D7=""),"",(SUMIFS(PORTFOLIO!$U$6:$U$55,PORTFOLIO!$E$6:$E$55,A7,PORTFOLIO!$X$6:$X$55,">30"))/D7) | G7: =IF(A7="","",SUMIF(REPAYMENTS!$E$5:$E$104,A7,REPAYMENTS!$F$5:$F$104)) | H7: =IF(OR(A7="",B7=0,B7=""),"",C7/B7)
B8: =IF(A8="","",COUNTIF(PORTFOLIO!$E$6:$E$55,A8)) | C8: =IF(A8="","",SUMIF(PORTFOLIO!$E$6:$E$55,A8,PORTFOLIO!$K$6:$K$55)) | D8: =IF(A8="","",SUMIF(PORTFOLIO!$E$6:$E$55,A8,PORTFOLIO!$U$6:$U$55)) | E8: =IF(A8="","",COUNTIFS(PORTFOLIO!$E$6:$E$55,A8,PORTFOLIO!$W$6:$W$55,">0")) | F8: =IF(OR(A8="",D8=0,D8=""),"",(SUMIFS(PORTFOLIO!$U$6:$U$55,PORTFOLIO!$E$6:$E$55,A8,PORTFOLIO!$X$6:$X$55,">30"))/D8) | G8: =IF(A8="","",SUMIF(REPAYMENTS!$E$5:$E$104,A8,REPAYMENTS!$F$5:$F$104)) | H8: =IF(OR(A8="",B8=0,B8=""),"",C8/B8)
B9: =IF(A9="","",COUNTIF(PORTFOLIO!$E$6:$E$55,A9)) | C9: =IF(A9="","",SUMIF(PORTFOLIO!$E$6:$E$55,A9,PORTFOLIO!$K$6:$K$55)) | D9: =IF(A9="","",SUMIF(PORTFOLIO!$E$6:$E$55,A9,PORTFOLIO!$U$6:$U$55)) | E9: =IF(A9="","",COUNTIFS(PORTFOLIO!$E$6:$E$55,A9,PORTFOLIO!$W$6:$W$55,">0")) | F9: =IF(OR(A9="",D9=0,D9=""),"",(SUMIFS(PORTFOLIO!$U$6:$U$55,PORTFOLIO!$E$6:$E$55,A9,PORTFOLIO!$X$6:$X$55,">30"))/D9) | G9: =IF(A9="","",SUMIF(REPAYMENTS!$E$5:$E$104,A9,REPAYMENTS!$F$5:$F$104)) | H9: =IF(OR(A9="",B9=0,B9=""),"",C9/B9)
B10: =IF(A10="","",COUNTIF(PORTFOLIO!$E$6:$E$55,A10)) | C10: =IF(A10="","",SUMIF(PORTFOLIO!$E$6:$E$55,A10,PORTFOLIO!$K$6:$K$55)) | D10: =IF(A10="","",SUMIF(PORTFOLIO!$E$6:$E$55,A10,PORTFOLIO!$U$6:$U$55)) | E10: =IF(A10="","",COUNTIFS(PORTFOLIO!$E$6:$E$55,A10,PORTFOLIO!$W$6:$W$55,">0")) | F10: =IF(OR(A10="",D10=0,D10=""),"",(SUMIFS(PORTFOLIO!$U$6:$U$55,PORTFOLIO!$E$6:$E$55,A10,PORTFOLIO!$X$6:$X$55,">30"))/D10) | G10: =IF(A10="","",SUMIF(REPAYMENTS!$E$5:$E$104,A10,REPAYMENTS!$F$5:$F$104)) | H10: =IF(OR(A10="",B10=0,B10=""),"",C10/B10)
B11: =IF(A11="","",COUNTIF(PORTFOLIO!$E$6:$E$55,A11)) | C11: =IF(A11="","",SUMIF(PORTFOLIO!$E$6:$E$55,A11,PORTFOLIO!$K$6:$K$55)) | D11: =IF(A11="","",SUMIF(PORTFOLIO!$E$6:$E$55,A11,PORTFOLIO!$U$6:$U$55)) | E11: =IF(A11="","",COUNTIFS(PORTFOLIO!$E$6:$E$55,A11,PORTFOLIO!$W$6:$W$55,">0")) | F11: =IF(OR(A11="",D11=0,D11=""),"",(SUMIFS(PORTFOLIO!$U$6:$U$55,PORTFOLIO!$E$6:$E$55,A11,PORTFOLIO!$X$6:$X$55,">30"))/D11) | G11: =IF(A11="","",SUMIF(REPAYMENTS!$E$5:$E$104,A11,REPAYMENTS!$F$5:$F$104)) | H11: =IF(OR(A11="",B11=0,B11=""),"",C11/B11)
B12: =IF(A12="","",COUNTIF(PORTFOLIO!$E$6:$E$55,A12)) | C12: =IF(A12="","",SUMIF(PORTFOLIO!$E$6:$E$55,A12,PORTFOLIO!$K$6:$K$55)) | D12: =IF(A12="","",SUMIF(PORTFOLIO!$E$6:$E$55,A12,PORTFOLIO!$U$6:$U$55)) | E12: =IF(A12="","",COUNTIFS(PORTFOLIO!$E$6:$E$55,A12,PORTFOLIO!$W$6:$W$55,">0")) | F12: =IF(OR(A12="",D12=0,D12=""),"",(SUMIFS(PORTFOLIO!$U$6:$U$55,PORTFOLIO!$E$6:$E$55,A12,PORTFOLIO!$X$6:$X$55,">30"))/D12) | G12: =IF(A12="","",SUMIF(REPAYMENTS!$E$5:$E$104,A12,REPAYMENTS!$F$5:$F$104)) | H12: =IF(OR(A12="",B12=0,B12=""),"",C12/B12)
B13: =IF(A13="","",COUNTIF(PORTFOLIO!$E$6:$E$55,A13)) | C13: =IF(A13="","",SUMIF(PORTFOLIO!$E$6:$E$55,A13,PORTFOLIO!$K$6:$K$55)) | D13: =IF(A13="","",SUMIF(PORTFOLIO!$E$6:$E$55,A13,PORTFOLIO!$U$6:$U$55)) | E13: =IF(A13="","",COUNTIFS(PORTFOLIO!$E$6:$E$55,A13,PORTFOLIO!$W$6:$W$55,">0")) | F13: =IF(OR(A13="",D13=0,D13=""),"",(SUMIFS(PORTFOLIO!$U$6:$U$55,PORTFOLIO!$E$6:$E$55,A13,PORTFOLIO!$X$6:$X$55,">30"))/D13) | G13: =IF(A13="","",SUMIF(REPAYMENTS!$E$5:$E$104,A13,REPAYMENTS!$F$5:$F$104)) | H13: =IF(OR(A13="",B13=0,B13=""),"",C13/B13)
B14: =IF(A14="","",COUNTIF(PORTFOLIO!$E$6:$E$55,A14)) | C14: =IF(A14="","",SUMIF(PORTFOLIO!$E$6:$E$55,A14,PORTFOLIO!$K$6:$K$55)) | D14: =IF(A14="","",SUMIF(PORTFOLIO!$E$6:$E$55,A14,PORTFOLIO!$U$6:$U$55)) | E14: =IF(A14="","",COUNTIFS(PORTFOLIO!$E$6:$E$55,A14,PORTFOLIO!$W$6:$W$55,">0")) | F14: =IF(OR(A14="",D14=0,D14=""),"",(SUMIFS(PORTFOLIO!$U$6:$U$55,PORTFOLIO!$E$6:$E$55,A14,PORTFOLIO!$X$6:$X$55,">30"))/D14) | G14: =IF(A14="","",SUMIF(REPAYMENTS!$E$5:$E$104,A14,REPAYMENTS!$F$5:$F$104)) | H14: =IF(OR(A14="",B14=0,B14=""),"",C14/B14)
B15: =IF(A15="","",COUNTIF(PORTFOLIO!$E$6:$E$55,A15)) | C15: =IF(A15="","",SUMIF(PORTFOLIO!$E$6:$E$55,A15,PORTFOLIO!$K$6:$K$55)) | D15: =IF(A15="","",SUMIF(PORTFOLIO!$E$6:$E$55,A15,PORTFOLIO!$U$6:$U$55)) | E15: =IF(A15="","",COUNTIFS(PORTFOLIO!$E$6:$E$55,A15,PORTFOLIO!$W$6:$W$55,">0")) | F15: =IF(OR(A15="",D15=0,D15=""),"",(SUMIFS(PORTFOLIO!$U$6:$U$55,PORTFOLIO!$E$6:$E$55,A15,PORTFOLIO!$X$6:$X$55,">30"))/D15) | G15: =IF(A15="","",SUMIF(REPAYMENTS!$E$5:$E$104,A15,REPAYMENTS!$F$5:$F$104)) | H15: =IF(OR(A15="",B15=0,B15=""),"",C15/B15)
B16: =IF(A16="","",COUNTIF(PORTFOLIO!$E$6:$E$55,A16)) | C16: =IF(A16="","",SUMIF(PORTFOLIO!$E$6:$E$55,A16,PORTFOLIO!$K$6:$K$55)) | D16: =IF(A16="","",SUMIF(PORTFOLIO!$E$6:$E$55,A16,PORTFOLIO!$U$6:$U$55)) | E16: =IF(A16="","",COUNTIFS(PORTFOLIO!$E$6:$E$55,A16,PORTFOLIO!$W$6:$W$55,">0")) | F16: =IF(OR(A16="",D16=0,D16=""),"",(SUMIFS(PORTFOLIO!$U$6:$U$55,PORTFOLIO!$E$6:$E$55,A16,PORTFOLIO!$X$6:$X$55,">30"))/D16) | G16: =IF(A16="","",SUMIF(REPAYMENTS!$E$5:$E$104,A16,REPAYMENTS!$F$5:$F$104)) | H16: =IF(OR(A16="",B16=0,B16=""),"",C16/B16)
B17: =IF(A17="","",COUNTIF(PORTFOLIO!$E$6:$E$55,A17)) | C17: =IF(A17="","",SUMIF(PORTFOLIO!$E$6:$E$55,A17,PORTFOLIO!$K$6:$K$55)) | D17: =IF(A17="","",SUMIF(PORTFOLIO!$E$6:$E$55,A17,PORTFOLIO!$U$6:$U$55)) | E17: =IF(A17="","",COUNTIFS(PORTFOLIO!$E$6:$E$55,A17,PORTFOLIO!$W$6:$W$55,">0")) | F17: =IF(OR(A17="",D17=0,D17=""),"",(SUMIFS(PORTFOLIO!$U$6:$U$55,PORTFOLIO!$E$6:$E$55,A17,PORTFOLIO!$X$6:$X$55,">30"))/D17) | G17: =IF(A17="","",SUMIF(REPAYMENTS!$E$5:$E$104,A17,REPAYMENTS!$F$5:$F$104)) | H17: =IF(OR(A17="",B17=0,B17=""),"",C17/B17)
... B19: =IF(A19="","",COUNTIF(PORTFOLIO!$E$6:$E$55,A19)) | C19: =IF(A19="","",SUMIF(PORTFOLIO!$E$6:$E$55,A19,PORTFOLIO!$K$6:$K$55)) | D19: =IF(A19="","",SUMIF(PORTFOLIO!$E$6:$E$55,A19,PORTFOLIO!$U$6:$U$55)) | E19: =IF(A19="","",COUNTIFS(PORTFOLIO!$E$6:$E$55,A19,PORTFOLIO!$W$6:$W$55,">0")) | F19: =IF(OR(A19="",D19=0,D19=""),"",(SUMIFS(PORTFOLIO!$U$6:$U$55,PORTFOLIO!$E$6:$E$55,A19,PORTFOLIO!$X$6:$X$55,">30"))/D19) | G19: =IF(A19="","",SUMIF(REPAYMENTS!$E$5:$E$104,A19,REPAYMENTS!$F$5:$F$104)) | H19: =IF(OR(A19="",B19=0,B19=""),"",C19/B19)

Sheet WRITEOFFS
A1: WRITEOFFS | Write-off Register
A2: Jopetnah International Limited | Version 1.0 | As at 01 Oct 2026 | Loans formally removed from the active portfolio as bad debt
A3: Amount Written Off is entered manually as a point-in-time decision (the live Outstanding Balance on PORTFOLIO keeps moving, so it is not a reliable source for a historical write-off figure). Set the loan's Status to "Written Off" on PORTFOLIO when you add a row here.
A5: Write-off ID | B5: Loan ID | C5: Borrower Name | D5: Write-off Date | E5: Amount Written Off (UGX) | F5: Reason | G5: Approved By | H5: Amount Recovered Since (UGX) | I5: Net Loss (UGX) | J5: Notes
C6: =IFERROR(IF(B6="","",VLOOKUP(B6,PORTFOLIO!$A:$C,3,0)),"Loan ID not found") | I6: =IF(E6="","",E6-IF(H6="",0,H6))
C7: =IFERROR(IF(B7="","",VLOOKUP(B7,PORTFOLIO!$A:$C,3,0)),"Loan ID not found") | I7: =IF(E7="","",E7-IF(H7="",0,H7))
C8: =IFERROR(IF(B8="","",VLOOKUP(B8,PORTFOLIO!$A:$C,3,0)),"Loan ID not found") | I8: =IF(E8="","",E8-IF(H8="",0,H8))
C9: =IFERROR(IF(B9="","",VLOOKUP(B9,PORTFOLIO!$A:$C,3,0)),"Loan ID not found") | I9: =IF(E9="","",E9-IF(H9="",0,H9))
C10: =IFERROR(IF(B10="","",VLOOKUP(B10,PORTFOLIO!$A:$C,3,0)),"Loan ID not found") | I10: =IF(E10="","",E10-IF(H10="",0,H10))
C11: =IFERROR(IF(B11="","",VLOOKUP(B11,PORTFOLIO!$A:$C,3,0)),"Loan ID not found") | I11: =IF(E11="","",E11-IF(H11="",0,H11))
C12: =IFERROR(IF(B12="","",VLOOKUP(B12,PORTFOLIO!$A:$C,3,0)),"Loan ID not found") | I12: =IF(E12="","",E12-IF(H12="",0,H12))
C13: =IFERROR(IF(B13="","",VLOOKUP(B13,PORTFOLIO!$A:$C,3,0)),"Loan ID not found") | I13: =IF(E13="","",E13-IF(H13="",0,H13))
C14: =IFERROR(IF(B14="","",VLOOKUP(B14,PORTFOLIO!$A:$C,3,0)),"Loan ID not found") | I14: =IF(E14="","",E14-IF(H14="",0,H14))
C15: =IFERROR(IF(B15="","",VLOOKUP(B15,PORTFOLIO!$A:$C,3,0)),"Loan ID not found") | I15: =IF(E15="","",E15-IF(H15="",0,H15))
C16: =IFERROR(IF(B16="","",VLOOKUP(B16,PORTFOLIO!$A:$C,3,0)),"Loan ID not found") | I16: =IF(E16="","",E16-IF(H16="",0,H16))
C17: =IFERROR(IF(B17="","",VLOOKUP(B17,PORTFOLIO!$A:$C,3,0)),"Loan ID not found") | I17: =IF(E17="","",E17-IF(H17="",0,H17))
... C25: =IFERROR(IF(B25="","",VLOOKUP(B25,PORTFOLIO!$A:$C,3,0)),"Loan ID not found") | I25: =IF(E25="","",E25-IF(H25="",0,H25))

Sheet AMORT
A1: AMORT | Loan Amortisation Schedule (Single Loan)
A2: Jopetnah International Limited | Version 1.0 | As at 01 Oct 2026 | Printable repayment schedule for one loan at a time
A3: Pick a Loan ID below — the loan's details pull in automatically from PORTFOLIO, and the full schedule generates beneath. Capped at 60 installments (5 years monthly); rows beyond the loan's term are left blank. The two "Check" cells at the bottom confirm the schedule's total principal and total interest reconcile exactly to PORTFOLIO's figures — if either ever shows "CHECK", do not rely on the schedule until the mismatch is investigated.
A5: Select Loan ID: | B5: L-0001
A7: Borrower | B7: =IFERROR(VLOOKUP($B$5,PORTFOLIO!$A:$C,3,0),"Loan ID not found") -> Example Borrower
A8: Branch / Location | B8: =IFERROR(VLOOKUP($B$5,PORTFOLIO!$A:$D,4,0),"Loan ID not found") -> Kampala (Head Office)
A9: Loan Officer | B9: =IFERROR(VLOOKUP($B$5,PORTFOLIO!$A:$E,5,0),"Loan ID not found") -> Example Loan Officer
A10: Loan Product | B10: =IFERROR(VLOOKUP($B$5,PORTFOLIO!$A:$F,6,0),"Loan ID not found") -> Business Growth Loan
A11: Interest Method | B11: =IFERROR(VLOOKUP($B$5,PORTFOLIO!$A:$I,9,0),"Loan ID not found") -> Reducing Balance
A12: Interest Rate (% p.a.) | B12: =IFERROR(VLOOKUP($B$5,PORTFOLIO!$A:$J,10,0),"Loan ID not found") -> 24
A13: Principal (UGX) | B13: =IFERROR(VLOOKUP($B$5,PORTFOLIO!$A:$K,11,0),"Loan ID not found") -> 5000000
A14: Term (Months) | B14: =IFERROR(VLOOKUP($B$5,PORTFOLIO!$A:$L,12,0),"Loan ID not found") -> 12
A15: Disbursement Date | B15: =IFERROR(VLOOKUP($B$5,PORTFOLIO!$A:$N,14,0),"Loan ID not found") -> 46037
A16: First Repayment Date | B16: =IFERROR(VLOOKUP($B$5,PORTFOLIO!$A:$O,15,0),"Loan ID not found") -> 46068
A17: Installment Amount (UGX) | B17: =IFERROR(VLOOKUP($B$5,PORTFOLIO!$A:$Q,17,0),"Loan ID not found") -> 472797.98
A19: Installment No. | B19: Due Date | C19: Opening Balance (UGX) | D19: Interest (UGX) | E19: Principal (UGX) | F19: Installment (UGX) | G19: Closing Balance (UGX)
A20: 1 | B20: =IF(1>B14,"",IF(B16="","",EDATE(B16,1-1))) -> 46068 | C20: =IF(1>B14,"",B13) -> 5000000 | D20: =IF(OR(1>B14,C20=""),"",IF(B11="Flat Rate",(B17*B14-B13)/B14,C20*B12/1200)) -> 100000 | E20: =IF(OR(1>B14,C20=""),"",IF(1=B14,C20,IF(B11="Flat Rate",B13/B14,B17-D20))) -> 372797.98 | F20: =IF(OR(1>B14,C20=""),"",D20+E20) -> 472797.98 | G20: =IF(OR(1>B14,C20=""),"",MAX(0,C20-E20)) -> 4627202
A21: 2 | B21: =IF(2>B14,"",IF(B16="","",EDATE(B16,2-1))) -> 46096 | C21: =IF(2>B14,"",IF(G20="","",G20)) -> 4627202 | D21: =IF(OR(2>B14,C21=""),"",IF(B11="Flat Rate",(B17*B14-B13)/B14,C21*B12/1200)) -> 92544.04 | E21: =IF(OR(2>B14,C21=""),"",IF(2=B14,C21,IF(B11="Flat Rate",B13/B14,B17-D21))) -> 380253.94 | F21: =IF(OR(2>B14,C21=""),"",D21+E21) -> 472797.98 | G21: =IF(OR(2>B14,C21=""),"",MAX(0,C21-E21)) -> 4246948.1
A22: 3 | B22: =IF(3>B14,"",IF(B16="","",EDATE(B16,3-1))) -> 46127 | C22: =IF(3>B14,"",IF(G21="","",G21)) -> 4246948.1 | D22: =IF(OR(3>B14,C22=""),"",IF(B11="Flat Rate",(B17*B14-B13)/B14,C22*B12/1200)) -> 84938.961 | E22: =IF(OR(3>B14,C22=""),"",IF(3=B14,C22,IF(B11="Flat Rate",B13/B14,B17-D22))) -> 387859.02 | F22: =IF(OR(3>B14,C22=""),"",D22+E22) -> 472797.98 | G22: =IF(OR(3>B14,C22=""),"",MAX(0,C22-E22)) -> 3859089.1
A23: 4 | B23: =IF(4>B14,"",IF(B16="","",EDATE(B16,4-1))) -> 46157 | C23: =IF(4>B14,"",IF(G22="","",G22)) -> 3859089.1 | D23: =IF(OR(4>B14,C23=""),"",IF(B11="Flat Rate",(B17*B14-B13)/B14,C23*B12/1200)) -> 77181.781 | E23: =IF(OR(4>B14,C23=""),"",IF(4=B14,C23,IF(B11="Flat Rate",B13/B14,B17-D23))) -> 395616.2 | F23: =IF(OR(4>B14,C23=""),"",D23+E23) -> 472797.98 | G23: =IF(OR(4>B14,C23=""),"",MAX(0,C23-E23)) -> 3463472.9
A24: 5 | B24: =IF(5>B14,"",IF(B16="","",EDATE(B16,5-1))) -> 46188 | C24: =IF(5>B14,"",IF(G23="","",G23)) -> 3463472.9 | D24: =IF(OR(5>B14,C24=""),"",IF(B11="Flat Rate",(B17*B14-B13)/B14,C24*B12/1200)) -> 69269.457 | E24: =IF(OR(5>B14,C24=""),"",IF(5=B14,C24,IF(B11="Flat Rate",B13/B14,B17-D24))) -> 403528.53 | F24: =IF(OR(5>B14,C24=""),"",D24+E24) -> 472797.98 | G24: =IF(OR(5>B14,C24=""),"",MAX(0,C24-E24)) -> 3059944.3
A25: 6 | B25: =IF(6>B14,"",IF(B16="","",EDATE(B16,6-1))) -> 46218 | C25: =IF(6>B14,"",IF(G24="","",G24)) -> 3059944.3 | D25: =IF(OR(6>B14,C25=""),"",IF(B11="Flat Rate",(B17*B14-B13)/B14,C25*B12/1200)) -> 61198.886 | E25: =IF(OR(6>B14,C25=""),"",IF(6=B14,C25,IF(B11="Flat Rate",B13/B14,B17-D25))) -> 411599.1 | F25: =IF(OR(6>B14,C25=""),"",D25+E25) -> 472797.98 | G25: =IF(OR(6>B14,C25=""),"",MAX(0,C25-E25)) -> 2648345.2
A26: 7 | B26: =IF(7>B14,"",IF(B16="","",EDATE(B16,7-1))) -> 46249 | C26: =IF(7>B14,"",IF(G25="","",G25)) -> 2648345.2 | D26: =IF(OR(7>B14,C26=""),"",IF(B11="Flat Rate",(B17*B14-B13)/B14,C26*B12/1200)) -> 52966.905 | E26: =IF(OR(7>B14,C26=""),"",IF(7=B14,C26,IF(B11="Flat Rate",B13/B14,B17-D26))) -> 419831.08 | F26: =IF(OR(7>B14,C26=""),"",D26+E26) -> 472797.98 | G26: =IF(OR(7>B14,C26=""),"",MAX(0,C26-E26)) -> 2228514.1
A27: 8 | B27: =IF(8>B14,"",IF(B16="","",EDATE(B16,8-1))) -> 46280 | C27: =IF(8>B14,"",IF(G26="","",G26)) -> 2228514.1 | D27: =IF(OR(8>B14,C27=""),"",IF(B11="Flat Rate",(B17*B14-B13)/B14,C27*B12/1200)) -> 44570.283 | E27: =IF(OR(8>B14,C27=""),"",IF(8=B14,C27,IF(B11="Flat Rate",B13/B14,B17-D27))) -> 428227.7 | F27: =IF(OR(8>B14,C27=""),"",D27+E27) -> 472797.98 | G27: =IF(OR(8>B14,C27=""),"",MAX(0,C27-E27)) -> 1800286.4
A28: 9 | B28: =IF(9>B14,"",IF(B16="","",EDATE(B16,9-1))) -> 46310 | C28: =IF(9>B14,"",IF(G27="","",G27)) -> 1800286.4 | D28: =IF(OR(9>B14,C28=""),"",IF(B11="Flat Rate",(B17*B14-B13)/B14,C28*B12/1200)) -> 36005.729 | E28: =IF(OR(9>B14,C28=""),"",IF(9=B14,C28,IF(B11="Flat Rate",B13/B14,B17-D28))) -> 436792.25 | F28: =IF(OR(9>B14,C28=""),"",D28+E28) -> 472797.98 | G28: =IF(OR(9>B14,C28=""),"",MAX(0,C28-E28)) -> 1363494.2
A29: 10 | B29: =IF(10>B14,"",IF(B16="","",EDATE(B16,10-1))) -> 46341 | C29: =IF(10>B14,"",IF(G28="","",G28)) -> 1363494.2 | D29: =IF(OR(10>B14,C29=""),"",IF(B11="Flat Rate",(B17*B14-B13)/B14,C29*B12/1200)) -> 27269.884 | E29: =IF(OR(10>B14,C29=""),"",IF(10=B14,C29,IF(B11="Flat Rate",B13/B14,B17-D29))) -> 445528.1 | F29: =IF(OR(10>B14,C29=""),"",D29+E29) -> 472797.98 | G29: =IF(OR(10>B14,C29=""),"",MAX(0,C29-E29)) -> 917966.1
A30: 11 | B30: =IF(11>B14,"",IF(B16="","",EDATE(B16,11-1))) -> 46371 | C30: =IF(11>B14,"",IF(G29="","",G29)) -> 917966.1 | D30: =IF(OR(11>B14,C30=""),"",IF(B11="Flat Rate",(B17*B14-B13)/B14,C30*B12/1200)) -> 18359.322 | E30: =IF(OR(11>B14,C30=""),"",IF(11=B14,C30,IF(B11="Flat Rate",B13/B14,B17-D30))) -> 454438.66 | F30: =IF(OR(11>B14,C30=""),"",D30+E30) -> 472797.98 | G30: =IF(OR(11>B14,C30=""),"",MAX(0,C30-E30)) -> 463527.43
A31: 12 | B31: =IF(12>B14,"",IF(B16="","",EDATE(B16,12-1))) -> 46402 | C31: =IF(12>B14,"",IF(G30="","",G30)) -> 463527.43 | D31: =IF(OR(12>B14,C31=""),"",IF(B11="Flat Rate",(B17*B14-B13)/B14,C31*B12/1200)) -> 9270.5487 | E31: =IF(OR(12>B14,C31=""),"",IF(12=B14,C31,IF(B11="Flat Rate",B13/B14,B17-D31))) -> 463527.43 | F31: =IF(OR(12>B14,C31=""),"",D31+E31) -> 472797.98 | G31: =IF(OR(12>B14,C31=""),"",MAX(0,C31-E31)) -> 0
A32: 13 | B32: =IF(13>B14,"",IF(B16="","",EDATE(B16,13-1))) | C32: =IF(13>B14,"",IF(G31="","",G31)) | D32: =IF(OR(13>B14,C32=""),"",IF(B11="Flat Rate",(B17*B14-B13)/B14,C32*B12/1200)) | E32: =IF(OR(13>B14,C32=""),"",IF(13=B14,C32,IF(B11="Flat Rate",B13/B14,B17-D32))) | F32: =IF(OR(13>B14,C32=""),"",D32+E32) | G32: =IF(OR(13>B14,C32=""),"",MAX(0,C32-E32))
A33: 14 | B33: =IF(14>B14,"",IF(B16="","",EDATE(B16,14-1))) | C33: =IF(14>B14,"",IF(G32="","",G32)) | D33: =IF(OR(14>B14,C33=""),"",IF(B11="Flat Rate",(B17*B14-B13)/B14,C33*B12/1200)) | E33: =IF(OR(14>B14,C33=""),"",IF(14=B14,C33,IF(B11="Flat Rate",B13/B14,B17-D33))) | F33: =IF(OR(14>B14,C33=""),"",D33+E33) | G33: =IF(OR(14>B14,C33=""),"",MAX(0,C33-E33))
A34: 15 | B34: =IF(15>B14,"",IF(B16="","",EDATE(B16,15-1))) | C34: =IF(15>B14,"",IF(G33="","",G33)) | D34: =IF(OR(15>B14,C34=""),"",IF(B11="Flat Rate",(B17*B14-B13)/B14,C34*B12/1200)) | E34: =IF(OR(15>B14,C34=""),"",IF(15=B14,C34,IF(B11="Flat Rate",B13/B14,B17-D34))) | F34: =IF(OR(15>B14,C34=""),"",D34+E34) | G34: =IF(OR(15>B14,C34=""),"",MAX(0,C34-E34))
A35: 16 | B35: =IF(16>B14,"",IF(B16="","",EDATE(B16,16-1))) | C35: =IF(16>B14,"",IF(G34="","",G34)) | D35: =IF(OR(16>B14,C35=""),"",IF(B11="Flat Rate",(B17*B14-B13)/B14,C35*B12/1200)) | E35: =IF(OR(16>B14,C35=""),"",IF(16=B14,C35,IF(B11="Flat Rate",B13/B14,B17-D35))) | F35: =IF(OR(16>B14,C35=""),"",D35+E35) | G35: =IF(OR(16>B14,C35=""),"",MAX(0,C35-E35))
A36: 17 | B36: =IF(17>B14,"",IF(B16="","",EDATE(B16,17-1))) | C36: =IF(17>B14,"",IF(G35="","",G35)) | D36: =IF(OR(17>B14,C36=""),"",IF(B11="Flat Rate",(B17*B14-B13)/B14,C36*B12/1200)) | E36: =IF(OR(17>B14,C36=""),"",IF(17=B14,C36,IF(B11="Flat Rate",B13/B14,B17-D36))) | F36: =IF(OR(17>B14,C36=""),"",D36+E36) | G36: =IF(OR(17>B14,C36=""),"",MAX(0,C36-E36))
A37: 18 | B37: =IF(18>B14,"",IF(B16="","",EDATE(B16,18-1))) | C37: =IF(18>B14,"",IF(G36="","",G36)) | D37: =IF(OR(18>B14,C37=""),"",IF(B11="Flat Rate",(B17*B14-B13)/B14,C37*B12/1200)) | E37: =IF(OR(18>B14,C37=""),"",IF(18=B14,C37,IF(B11="Flat Rate",B13/B14,B17-D37))) | F37: =IF(OR(18>B14,C37=""),"",D37+E37) | G37: =IF(OR(18>B14,C37=""),"",MAX(0,C37-E37))
A38: 19 | B38: =IF(19>B14,"",IF(B16="","",EDATE(B16,19-1))) | C38: =IF(19>B14,"",IF(G37="","",G37)) | D38: =IF(OR(19>B14,C38=""),"",IF(B11="Flat Rate",(B17*B14-B13)/B14,C38*B12/1200)) | E38: =IF(OR(19>B14,C38=""),"",IF(19=B14,C38,IF(B11="Flat Rate",B13/B14,B17-D38))) | F38: =IF(OR(19>B14,C38=""),"",D38+E38) | G38: =IF(OR(19>B14,C38=""),"",MAX(0,C38-E38))
